Workbook
Name ggg: 'Raw Data (2)'!$A$1:$A$4
Name ggg: 'Raw Data (3)'!$A$1:$A$4
Name ggg: 'Raw Data (4)'!$A$1:$A$4
Name ggg: 'Raw Data'!$A$1:$A$4
Name NativeTimeline_Order_Date1: #N/A
Name Slicer_Region1: #N/A

Sheet Raw Data (3)
A1: Order ID | B1: Order Date | C1: Ship Date | D1: Ship Mode | E1: First Name | F1: Last Name | G1: Email | H1: Phone | I1: Segment | J1: Region | K1: State | L1: Category | M1: Sub-Category | N1: Product Name | O1: Quantity | P1: Unit Price (₦) | Q1: Discount (%) | R1: Discount Amount (₦) | S1: Sales (₦) | T1: Profit (₦)
A2: ORD-10858 | B2: 44562 | C2: 44567 | D2: Standard Class | E2: Ayo | F2: Adeleke | G2: ayo.adeleke@gmail.com | H2: 8161000159 | I2: Consumer | J2: East | K2: Onitsha | L2: Office Supplies | M2: Envelopes | N2: Brown Kraft Envelopes | O2: 6 | P2: 18354.33 | Q2: 0 | R2: 0 | S2: 110125.98 | T2: -12981.35 | U2: =VALUE(S2) -> 110125.98
A3: ORD-10268 | B3: 44562 | C3: 44565 | D3: Second Class | E3: Sade | F3: Chukwu | G3: sade.chukwu@hotmail.com | H3: 7037629401 | I3: Corporate | J3: South | K3: Lagos | L3: Clothing | M3: Accessories | N3: Sunglasses UV400 | O3: 3 | P3: 24262.94 | Q3: 0 | R3: 0 | S3: 72788.82 | T3: 13084.2 | U3: =VALUE(S3) -> 72788.82
A4: ORD-10867 | B4: 44563 | C4: 44568 | D4: Second Class | E4: Yemi | F4: Sanusi | G4: email.com | H4: 8066143155 | I4: Home Office | K4: Ilorin | L4: Furniture | M4: Storage | N4: Plastic Drawers | O4: 18 | P4: 149939.9 | Q4: 0 | R4: 0 | S4: 2698918.2 | T4: 1136056.6 | U4: =VALUE(S4) -> 2698918.2
A5: ORD-10470 | B5: 44563 | C5: 44566 | D5: Second Class | E5: Kunle | F5: Chukwu | G5: kunle.chukwu@outlook.com | H5: 8037377917 | I5: Corporate | J5: West | K5: Ado-Ekiti | L5: oFFICE sUPPLIES | M5: Art Supplies | N5: Acrylic Paint Kit | O5: 17 | P5: 14836.4 | Q5: 10 | R5: 25221.88 | S5: 226996.92 | T5: -27854.6 | U5: =VALUE(S5) -> 226996.92
A6: ORD-10631 | B6: 44564 | C6: 44565 | D6: Same Day | E6: Hauwa | F6: Sanusi | G6: hauwa.sanusi@gmail.com | H6: 8031291769 | I6: corporate | J6: North | K6: Katsina | L6: Food & Beverages | M6: Grains | N6: Semolina 5kg | O6: 6 | P6: 4344.57 | Q6: 0 | R6: 0 | S6: 26067.42 | T6: 8215.25 | U6: =VALUE(S6) -> 26067.42
A7: ORD-10377 | B7: 44564 | C7: 44564 | D7: Same Day | E7: Chidinma | F7: Obi | G7: chidinma.obi@outlook.com | H7: 8151548852 | I7: Corporate | J7: West | K7: Ilorin | L7: Office Supplies | M7: Envelopes | N7: Padded Envelopes | O7: 20 | P7: 17602.35 | Q7: 25 | R7: 88011.75 | S7: 264035.25 | T7: 51523.21 | U7: =VALUE(S7) -> 264035.25
A8: ORD-10862 | B8: 44565 | C8: 44565 | D8: Same Day | E8: Kehinde | F8: Gambo | G8: kehinde.gambo@hotmail.com | H8: 8159196133 | I8: Consumer | J8: East | K8: Onitsha | L8: Furniture | M8: Chairs | N8: Visitor Chair | O8: 20 | P8: 70613.98 | Q8: 10 | R8: 141227.96 | S8: 1271051.6 | T8: 157298.35 | U8: =VALUE(S8) -> 1271051.6
A9: ORD-10528 | B9: 44568 | C9: 44573 | D9: Second Class | E9: Chisom | F9: Okonkwo | G9: chisom.okonkwo@outlook.com | H9: 8031767629 | I9: Corporate | J9: West | K9: Ado-Ekiti | L9: Office Supplies | M9: Fasteners | N9: Rubber Bands 100g | O9: 16 | P9: 6222.19 | Q9: 15 | R9: 14933.26 | S9: 84621.78 | T9: 24838.42 | U9: =VALUE(S9) -> 84621.78
A10: ORD-10652 | B10: 44572 | C10: 44576 | D10: Second Class | E10: Chibundo | F10: Danjuma | G10: chibundo.danjuma@gmail.com | H10: 7034108891 | I10: Consumer | J10: North | K10: Kaduna | L10: Food & Beverages | M10: Cooking Oil | N10: Palm Oil 4L | O10: 19 | P10: 6709.5 | Q10: 20 | R10: 25496.1 | S10: 101984.4 | T10: 15349.69 | U10: =VALUE(S10) -> 101984.4
A11: ORD-10441 | B11: 44573 | C11: 44581 | D11: Standard Class | E11: Bola | F11: Okonkwo | G11: bola.okonkwo@yahoo.com | H11: 9079004743 | I11: Corporate | J11: East | K11: Enugu | L11: Clothing | M11: Bags | N11: Crossbody Bag | O11: 10 | P11: 33214.19 | Q11: 10 | R11: 33214.19 | S11: 298927.71 | T11: 79035.7 | U11: =VALUE(S11) -> 298927.71
A12: ORD-10486 | B12: 44575 | C12: 44579 | D12: Second Class | E12: Chidi | F12: Musa | G12: INVALID | H12: 8032932555 | I12: Corporate | J12: West | K12: Ilorin | L12: Furniture | M12: Bookcases | N12: Corner Bookshelf | O12: 19 | P12: 41437.39 | Q12: 10 | R12: 78731.04 | S12: 708579.37 | T12: -87620.87 | U12: =VALUE(S12) -> 708579.37
A13: ORD-10643 | B13: 44575 | C13: 44578 | D13: First Class | E13: Ayo | F13: Obi | G13: ayo.obi@yahoo.com | H13: 8062126456 | I13: Home Office | J13: South | K13: Benin City | L13: Technology | M13: Phones | N13: Xiaomi Redmi 12 | O13: 17 | P13: 397756.09 | Q13: 0 | R13: 0 | S13: 6761853.5 | T13: -11335.22 | U13: =VALUE(S13) -> 6761853.5
A14: ORD-10799 | B14: 44575 | C14: 44577 | D14: First Class | E14: Obinna | F14: Danjuma | G14: obinna.danjuma@gmail.com | H14: 9022191407 | I14: Home Office | J14: West | K14: Ilorin | L14: Food & Beverages | M14: Drinks | N14: Energy Drink 4-Pack | O14: 6 | P14: 3485.58 | Q14: 5 | R14: 1045.67 | S14: $19,867.81 | T14: -14.31 | U14: =VALUE(S14) -> #VALUE!
A15: ORD-10451 | B15: 44575 | C15: 44575 | D15: Same Day | E15: Kunle | F15: Osei | G15: kunle.osei@outlook.com | H15: 8153873296 | I15: Corporate | J15: North | K15: Kaduna | L15: Technology | M15: Tablets | N15: Lenovo Tab M10 | O15: 14 | P15: 326111.89 | Q15: 10 | R15: 456556.65 | S15: 4109009.8 | T15: 935474.6 | U15: =VALUE(S15) -> 4109009.8
A16: ORD-10288 | B16: 44578 | C16: 44578 | D16: Same Day | E16: Sade | F16: Okafor | G16: sade.okafor@gmail.com | H16: 8144643811 | I16: Consumer | J16: East | K16: Aba | L16: Office Supplies | M16: Envelopes | N16: Padded Envelopes | O16: 16 | P16: 19750.27 | Q16: 10 | R16: 31600.43 | S16: 284403.89 | T16: 36463.62 | U16: =VALUE(S16) -> 284403.89
A17: ORD-10568 | B17: 44580 | C17: 44585 | D17: Second Class | E17: Adebayo | F17: Dangote | G17: adebayo.dangote@outlook.com | H17: 8164696630 | I17: Home Office | J17: North | K17: Kaduna | L17: Office Supplies | M17: Fasteners | N17: Binder Clips Asst. | O17: 6 | P17: 14027.7 | Q17: 5 | R17: 4208.31 | S17: 79957.89 | T17: -9805.44 | U17: =VALUE(S17) -> 79957.89
A18: ORD-10538 | B18: 44580 | C18: 44584 | D18: SECOND CLASS | E18: Kehinde | F18: Bello | G18: kehinde.bello@yahoo.com | H18: 7068165734 | I18: Home Office | J18: South | K18: Ibadan | L18: Furniture | M18: Chairs | N18: Executive Chair | O18: 16 | P18: 69160.42 | Q18: 0 | R18: 0 | S18: 1106566.7 | T18: 461480.28 | U18: =VALUE(S18) -> 1106566.7
A19: ORD-10285 | B19: 44580 | C19: 44583 | D19: First Class | E19: Nike | F19: Alakija | G19: nike.alakija@yahoo.com | H19: 9021121097 | I19: Corporate | J19: North | K19: Sokoto | L19: Food & Beverages | M19: Grains | N19: Semolina 5kg | O19: 18 | P19: 3470.37 | Q19: 15 | R19: 9370 | S19: 53096.66 | T19: 4611.51 | U19: =VALUE(S19) -> 53096.66
A20: ORD-10667 | B20: 44580 | C20: 44581 | D20: Same Day | E20: Emeka | F20: Adebayo | G20: emeka.adebayo@hotmail.com | H20: 9074654790 | I20: Consumer | J20: West | K20: Akure | L20: Clothing | M20: Shirts | N20: Ankara Print Shirt | O20: 9 | P20: 42369.87 | Q20: 25 | R20: 95332.21 | S20: 285996.62 | T20: 10986.82 | U20: =VALUE(S20) -> 285996.62
A21: ORD-10701 | B21: 44582 | C21: 44583 | D21: Same Day | G21: chibundo.adeyemi@yahoo.com | H21: 8142124878 | I21: Home Office | J21: South | K21: Ibadan | L21: Technology | M21: Tablets | N21: Samsung Tab A8 | O21: 4 | P21: 101681.42 | Q21: 25 | R21: 101681.42 | S21: 305044.26 | T21: 38178.16 | U21: =VALUE(S21) -> 305044.26
A22: ORD-10505 | B22: 44583 | C22: 44590 | D22: Standard Class | E22: Bola | F22: Obi | G22: bola.obi@yahoo.com | H22: 7038788747 | I22: Corporate | J22: West | K22: Ilorin | L22: Clothing | M22: Bags | N22: Laptop Backpack | O22: 8 | P22: 5549.59 | Q22: 20 | R22: 8879.34 | S22: 35517.38 | T22: -2338.7 | U22: =VALUE(S22) -> 35517.38
A23: ORD-10905 | B23: 44584 | C23: 44587 | D23: Second Class | E23: Seun | F23: Atiku | H23: 8031414120 | I23: Corporate | J23: East | K23: Onitsha | L23: Food & Beverages | M23: Snacks | N23: Plantain Chips 200g | O23: 15 | P23: 3158.75 | Q23: 15 | R23: 7107.19 | S23: 40274.06 | T23: 2030.8 | U23: =VALUE(S23) -> 40274.06
A24: ORD-10616 | B24: 44584 | C24: 44587 | D24: First Class | E24: Ibrahim | F24: Fashola | G24: ibrahim.fashola@outlook.com | H24: 8132111241 | I24: Consumer | J24: East | K24: Enugu | L24: Clothing | M24: Shoes | N24: Sandals | O24: 7 | P24: 11123.53 | Q24: 0 | R24: 0 | S24: 77864.71 | T24: 14527.63 | U24: =VALUE(S24) -> 77864.71
A25: ORD-10139 | B25: 44586 | C25: 44586 | D25: same day | E25: Ronke | F25: Atiku | G25: ronke.atiku@outlook.com | H25: 8155809835 | I25: Home Office | J25: North | K25: Kano | L25: Technology | M25: Printers | N25: Brother HL-L2350DW | O25: 6 | P25: 365682.95 | Q25: 0 | R25: 0 | S25: 2194097.7 | T25: 879458.66 | U25: =VALUE(S25) -> 2194097.7
A26: ORD-10521 | B26: 44587 | C26: 44590 | D26: Second Class | E26: Sade | F26: Tinubu | G26: sade.tinubu@hotmail.com | H26: 7062348021 | I26: Consumer | J26: South | K26: Benin City | L26: Food&Beverages | M26: Snacks | N26: Popcorn 6-Pack | O26: 14 | P26: 1576.84 | Q26: 10 | R26: 2207.58 | S26: 19868.18 | T26: 5267.1 | U26: =VALUE(S26) -> 19868.18
A27: ORD-10842 | B27: 44588 | C27: 44589 | D27: Same Day | E27: Aisha | F27: Osei | G27: aisha.osei@outlook.com | H27: 9078197382 | I27: Corporate | J27: West | K27: Ilorin | L27: Food & Beverages | M27: Drinks | N27: Energy Drink 4-Pack | O27: 10 | P27: 1296.6 | Q27: 10 | R27: 1296.6 | S27: 11669.4 | T27: 3324.08 | U27: =VALUE(S27) -> 11669.4
A28: ORD-10926 | B28: 44591 | C28: 44596 | D28: Second Class | E28: Oluwaseun | F28: Musa | G28: oluwaseun.musa@outlook.com | H28: 9075120422 | I28: Home Office | J28: East | K28: Onitsha | L28: Clothing | M28: Shirts | N28: Men's Polo Shirt | O28: 9 | P28: 7584.73 | Q28: 0 | R28: 0 | S28: 68262.57 | T28: 16688.44 | U28: =VALUE(S28) -> 68262.57
A29: ORD-10982 | B29: 44594 | C29: 44599 | D29: Second Class | E29: Olumide | F29: Chukwu | G29: olumide.chukwu@yahoo.com | H29: 7068058810 | I29: Corporate | J29: North | K29: Abuja | L29: fOOD & bEVERAGES | M29: Condiments | N29: Pepper Mix 200g | O29: 10 | P29: 6995.77 | Q29: 25 | R29: 17489.43 | S29: 52468.27 | T29: 12332.65 | U29: =VALUE(S29) -> 52468.27
A30: ORD-10903 | B30: 44595 | C30: 44598 | D30: Second Class | E30: Olumide | F30: Chukwu | G30: olumide.chukwu@hotmail.com | H30: 7068824038 | I30: Consumer | J30: East | K30: Owerri | L30: Clothing | M30: Shoes | N30: Women's Heels | O30: 14 | P30: 21921.87 | Q30: 0 | R30: 0 | S30: 306906.18 | T30: -853.32 | U30: =VALUE(S30) -> 306906.18
A31: ORD-10925 | B31: 44595 | C31: 44596 | D31: Same Day | E31: Deola | F31: Sowore | G31: deola.sowore@gmail.com | H31: 8144580502 | I31: Home Office | J31: East | K31: Awka | L31: Food & Beverages | M31: Condiments | N31: Soy Sauce 500ml | O31: 8 | P31: 6303.5 | Q31: 15 | R31: 7564.2 | S31: 42863.8 | T31: 7992.08 | U31: =VALUE(S31) -> 42863.8
A32: ORD-10363 | B32: 44595 | C32: 44595 | D32: Same Day | E32: Adaeze | F32: Adeleke | G32: adaeze.adeleke@outlook.com | H32: 9021718308 | I32: Home Office | J32: East | K32: Owerri | L32: Clothing | M32: Shirts | N32: Women's Blouse | O32: 17 | P32: 36705.46 | Q32: 20 | R32: 124798.56 | S32: 499194.26 | T32: 206693.32 | U32: =VALUE(S32) -> 499194.26
A33: ORD-10113 | B33: 44596 | C33: 44597 | D33: Same Day | E33: Adaeze | F33: Sowore | H33: 7066161977 | I33: Corporate | J33: West | K33: Ado-Ekiti | L33: Technology | M33: Printers | N33: Brother HL-L2350DW | O33: 19 | P33: 130505.74 | Q33: 5 | R33: 123980.45 | S33: 2355628.6 | T33: 666266.15 | U33: =VALUE(S33) -> 2355628.6
A34: ORD-10923 | B34: 44598 | C34: 44601 | D34: First Class | E34: Lanre | F34: Tinubu | G34: lanre.tinubu@gmail.com | H34: 8148000211 | I34: Corporate | J34: West | K34: Abeokuta | L34: Clothing | M34: Accessories | N34: Wallet Genuine Leather | O34: 11 | P34: 11930.65 | Q34: 5 | R34: 6561.86 | S34: 124675.29 | T34: 14906.53 | U34: =VALUE(S34) -> 124675.29
A35: ORD-10929 | B35: 44599 | C35: 44601 | D35: First Class | E35: Tunde | F35: Adeyemi | G35: tunde.adeyemi@yahoo.com | H35: 7033690055 | I35: Home Office | J35: West | K35: Ilorin | L35: Food & Beverages | M35: Condiments | N35: Maggi Cubes 100pk | O35: 12 | P35: 3985.92 | Q35: 0 | R35: 0 | S35: 47831.04 | T35: 2588.06 | U35: =VALUE(S35) -> 47831.04
A36: ORD-10618 | B36: 44605 | C36: 44609 | D36: Second Class | E36: Amara | F36: Tinubu | G36: amara.tinubu@gmail.com | H36: 8145770866 | I36: Corporate | J36: East | K36: Awka | L36: Furniture | M36: Storage | N36: 4-Drawer Cabinet | O36: 17 | P36: 162082.68 | Q36: 0 | R36: 0 | S36: 2755405.6 | T36: 144476.72 | U36: =VALUE(S36) -> 2755405.6
A37: ORD-10610 | B37: 44606 | D37: Same Day | E37: Tunde | F37: Sanusi | G37: spaces in@email.com | H37: 8138044872 | I37: Consumer | J37: SOTH | K37: Warri | L37: Clothing | M37: Shoes | N37: Leather Loafers | O37: 6 | P37: 36767.61 | Q37: 10 | R37: 22060.57 | S37: 198545.09 | T37: -28573.78 | U37: =VALUE(S37) -> 198545.09
A38: ORD-10382 | B38: 44607 | C38: 44613 | D38: STANDARD CLASS | E38: Ronke | F38: Tinubu | G38: ronke.tinubu@outlook.com | H38: 7066751103 | I38: Consumer | J38: North | K38: Abuja | L38: Office Supplies | M38: Envelopes | N38: C5 Envelopes | O38: 17 units | P38: 16813.46 | Q38: 25 | R38: 71457.21 | S38: 214371.61 | T38: 25114.44 | U38: =VALUE(S38) -> 214371.61
A39: ORD-10910 | B39: 44607 | C39: 44611 | D39: Second Class | E39: Kunle | F39: Chukwu | G39: kunle.chukwu@outlook.com | H39: 8156042710 | I39: Consumer | J39: East | K39: Awka | L39: Clothing | M39: Bags | N39: Laptop Backpack | O39: 10 | P39: 42940.32 | Q39: 10 | R39: 42940.32 | S39: 386462.88 | T39: -33275.2 | U39: =VALUE(S39) -> 386462.88
A40: ORD-10654 | B40: 44608 | C40: 44610 | D40: First Class | E40: Nike | F40: Gambo | G40: nike.gambo@outlook.com | H40: 7067004652 | I40: Home Office | J40: South | K40: Lagos | L40: Technology | M40: Phones | N40: Tecno Spark 10 | O40: 19 | P40: 47528.05 | Q40: 5 | R40: 45151.65 | S40: 857881.3 | T40: 310481.94 | U40: =VALUE(S40) -> 857881.3
...

Sheet Raw Data (2)
A1: Order ID | B1: Order Date | C1: Ship Date | D1: Ship Mode | E1: Customer Name | F1: Email | G1: Phone | H1: Segment | I1: Region | J1: State | K1: Category | L1: Sub-Category | M1: Product Name | N1: Quantity | O1: Unit Price (₦) | P1: Discount (%) | Q1: Discount Amount (₦) | R1: Sales (₦) | S1: Profit (₦)
A2: ORD-10001 | B2: 45063 | C2: 45065 | D2: First Class | E2: Kemi Atiku | F2: kemi.atiku@gmail.com | G2: 080 | H2: Home Office | I2: North | J2: Kano | K2: Food & Beverages | L2: Cooking Oil | M2: Vegetable Oil 5L | N2: 7 | O2: 529.44 | P2: 5% | Q2: 185.3 | R2: 3520.78 | S2: 539.43
A3: ORD-10002 | B3: 45013 | C3: 45014 | D3: Same Day | E3: Lanre Chukwu | F3: lanre.chukwu@gmail.com | G3: 9023678638 | H3: Consumer | I3: North | J3: Katsina | K3: clothing | L3: Shoes | M3: Sneakers Unisex | N3: 11 | O3: 8685.62 | P3: 0 | Q3: 0 | R3: 95541.82 | S3: -9014.61
A4: ORD-10003 | B4: 44650 | C4: 44653 | D4: First Class | E4: Bukola Bello | F4: bukola.bello@hotmail.com | G4: 8065918715 | H4: Corporate | I4: North | J4: Abuja | K4: Food & Beverages | L4: Grains | M4: Beans 5kg | N4: 3 | O4: 1780.62 | P4: 0 | Q4: 0 | R4: 5341.86 | S4: 1318.15
A5: ORD-10004 | B5: 45340 | C5: 45347 | D5: Standard Class | E5: Adebayo Tinubu | F5: adebayo.tinubu@outlook.com | G5: 8107210606 | H5: Consumer | I5: East | J5: Enugu | K5: office supplies | L5: Binders | M5: Clipboard | N5: 3 | O5: 17694.6 | P5: 0 | Q5: 0 | R5: 53083.8 | S5: 9049.93
A6: ORD-10005 | B6: 45114 | C6: 45114 | D6: Same Day | E6: Chisom Gambo | F6: chisom.gambo@gmail.com | G6: 00000000000 | H6: corporate | I6: South | J6: Ibadan | K6: Office Supplies | L6: Envelopes | M6: Padded Envelopes | N6: 19 | O6: 2121.62 | P6: 10 | Q6: 4031.08 | R6: 36279.7 | S6: -813.54
A7: ORD-10006 | B7: 44854 | C7: 44855 | D7: Same Day | E7: Kemi Abubakar | F7: kemi.abubakar@outlook.com | G7: 9018187926 | H7: Home Office | I7: West | J7: Akure | K7: Food & Beverages | L7: Cooking Oil | M7: Groundnut Oil 3L | N7: 5 | O7: 1988.77 | P7: 25 | Q7: 2485.96 | R7: 7457.89
A8: ORD-10007 | B8: 45426 | C8: 45431 | D8: Second Class | E8: Tunde Olawale | F8: tunde.olawale@hotmail.com | G8: 9058852574 | H8: Consumer | I8: North | J8: Kano | K8: Food & Beverages | L8: Grains | M8: Beans 5kg | N8: 1 | O8: 6928 | P8: 0 | Q8: 0 | R8: 6928 | S8: 1794.53
A9: ORD-10008 | B9: 45452 | C9: 45454 | D9: First Class | E9: Adebayo Okonkwo | F9: adebayo.okonkwo@outlook.com | G9: 8153997281 | H9: Consumer | I9: East | K9: Food & Beverages | L9: Drinks | M9: Water 5L x6 | N9: 17 | O9: 6780.85 | P9: 5 | Q9: 5763.72 | R9: 109510.73 | S9: -6384.09
A10: ORD-10009 | B10: 45225 | C10: 45233 | D10: Standard Class | E10: Amara Bello | F10: amara.bello@outlook.com | G10: 8036159230 | H10: Home Office | I10: South | J10: Port Harcourt | K10: Furniture | L10: Chairs | M10: Mesh Office Chair | N10: 3 | O10: 159017.65 | P10: 0 | Q10: 0 | R10: 477052.95 | S10: 137937.26
A11: ORD-10010 | B11: 45535 | C11: 45540 | D11: Second Class | E11: Aisha Chukwu | F11: aisha.chukwu@hotmail.com | G11: 8134374754 | H11: Consumer | I11: North | J11: Katsina | K11: Office Supplies | L11: Envelopes | M11: Padded Envelopes | N11: 17 | O11: 11233.45 | P11: 20 | Q11: 38193.73 | R11: 152774.92 | S11: -11824.39
A12: ORD-10011 | B12: 45033 | C12: 45039 | D12: Standard Class | E12: Chidi Musa | F12: chidi.musa@gmail.com | G12: +234 803 123 4567 | H12: Corporate | I12: South | J12: Lagos | K12: Technology | L12: Tablets | M12: iPad 10th Gen | N12: 9 | O12: 238657.91 | P12: 20 | Q12: 429584.24 | R12: 1718336.95 | S12: -36871.93
A13: ORD-10012 | B13: 45059 | C13: 45060 | D13: Same Day | E13: Chibundo Nwosu | F13: chibundo.nwosu@gmail.com | G13: 8068231838 | H13: Home Office | I13: South | J13: Port Harcourt | K13: Office Supplies | L13: Envelopes | M13: Brown Kraft Envelopes | N13: 2 | O13: 11942.1 | P13: 0 | Q13: 0 | R13: 23884.2 | S13: -2714.02
A14: ORD-10013 | B14: 44951 | C14: 44956 | D14: Second Class | E14: Olumide Okafor | F14: olumide.okafor@hotmail.com | G14: 8105673212 | H14: Consumer | I14: East | J14: Enugu | K14: Clothing | L14: Trousers | M14: Men's Chinos | N14: 18 | O14: 21054.62 | P14: 0 | Q14: 0 | R14: 378983.16 | S14: -45344.2
A15: ORD-10014 | B15: 45394 | C15: 45398 | D15: Second Class | E15: Kunle Nwosu | F15: kunle.nwosu@hotmail.com | G15: 8033762152 | H15: Consumer | I15: North | J15: Kano | K15: Clothing | L15: Shirts | M15: T-Shirt 3-Pack | N15: 15 | O15: 13403.73 | P15: 10 | Q15: 20105.59 | R15: 180950.36 | S15: 18783.46
A16: ORD-10015 | B16: 45007 | C16: 45009 | D16: First Class | E16: Lanre Atiku | F16: lanre.atiku@gmail.com | G16: 9016261415 | H16: Consumer | I16: West | J16: Ilorin | K16: Technology | L16: Laptops | M16: Acer Aspire 5 | N16: 17 | O16: 222403 | P16: 0 | Q16: 0 | R16: 3780851 | S16: -438095.72
A17: ORD-10016 | B17: 45043 | C17: 45051 | D17: Standard Class | E17: Bola Danjuma | F17: bola.danjuma@yahoo.com | G17: 9051666754 | H17: CONSUMER | I17: North | J17: Kaduna | K17: Food & Beverages | L17: Drinks | M17: Fruit Juice 1L | N17: 19 | O17: 5361.77 | P17: 25 | Q17: 25468.41 | R17: 76405.22 | S17: 3042.6
A18: ORD-10017 | B18: 45050 | C18: 45053 | D18: First Class | E18: Ikenna Okafor | F18: ikenna.okafor@outlook.com | G18: 8146304573 | H18: Home Office | I18: East | J18: Onitsha | K18: Technolgy | L18: Laptops | M18: Asus VivoBook 14 | N18: 19 | O18: 285204.28 | P18: 0 | Q18: 0 | R18: 5418881.3 | S18: -574637.51
A19: ORD-10018 | B19: 45276 | C19: 45279 | D19: Second Class | E19: Hauwa Adebayo | F19: hauwa.adebayo@outlook.com | G19: 8108351517 | H19: Corporate | I19: South | J19: Port Harcourt | K19: Food & Beverages | L19: Grains | M19: Beans 5kg | N19: 17 | O19: 7875.67 | P19: 0 | Q19: 0 | R19: 133886.39 | S19: 33567.72
A20: ORD-10019 | B20: 44798 | C20: 44800 | D20: First Class | E20: Taiwo Okafor | F20: taiwo.okafor@outlook.com | G20: 8164533779 | H20: Consumer | I20: East | J20: Enugu | K20: Office Supplies | L20: Binders | M20: Clipboard | N20: 9 units | O20: 12882.52 | P20: 0 | Q20: 0 | R20: 115942.68 | S20: -10970.6
A21: ORD-10020 | B21: 45245 | C21: 45251 | D21: Standard Class | E21: Tobi Adeyemi | F21: tobi.adeyemi@hotmail.com | G21: 8158175395 | H21: Consumer | I21: West | J21: Osogbo | K21: Food & Beverages | L21: Drinks | M21: Coca-Cola 24-Pack | N21: 5 | O21: 879.38 | P21: 25 | Q21: 1099.22 | R21: 3297.68 | S21: -423.37
A22: ORD-10021 | B22: 45442 | C22: 45445 | D22: Second Class | E22: Emeka Eze | F22: emeka.eze@outlook.com | G22: 9021669324 | H22: Home Office | I22: East | J22: Awka | K22: Office Supplies | L22: Binders | M22: Lever Arch File | N22: -1 | O22: 16839.87 | P22: 25 | Q22: 50519.61 | R22: 151558.83 | S22: 57665.23
A23: ORD-10022 | B23: 45046 | C23: 45049 | D23: Second Class | E23: Fatima Ogundipe | F23: fatima.ogundipe@gmail.com | G23: 8106573147 | H23: Home Office | I23: WSET | J23: Ado-Ekiti | K23: cLOTHING | L23: Trousers | M23: Joggers | N23: 4 | O23: 8845.51 | P23: 15 | Q23: 5307.31 | R23: 30074.73 | S23: 11226.9
A24: ORD-10023 | B24: 45278 | C24: 45279 | D24: Same Day | E24: Zainab Abubakar | F24: zainab.abubakar@gmail.com | G24: 9074240180 | H24: Consumer | I24: West | J24: Ilorin | K24: Clothing | L24: Shoes | M24: Sneakers Unisex | N24: 9 | O24: 39167.18 | P24: 10% | Q24: 35250.46 | R24: 317254.16 | S24: 74519.53
A25: ORD-10024 | B25: 44798 | C25: 44805 | D25: Standard Class | E25: Fatima Danjuma | F25: fatima.danjuma@outlook.com | G25: 8032818692 | H25: Corporate | I25: West | J25: Ado-Ekiti | K25: Food & Beverages | L25: Cooking Oil | M25: Groundnut Oil 3L | N25: 11 | O25: 5909.8 | P25: 15 | Q25: 9751.17 | R25: 55256.63 | S25: 11809.74
A26: ORD-10025 | B26: 45083 | C26: 45086 | D26: Second Class | E26: Oluwaseun Okonkwo | F26: oluwaseun.okonkwo@yahoo.com | G26: 7038235969 | H26: Home Office | I26: North | J26: Sokoto | K26: Technology | L26: Tablets | M26: Amazon Fire HD 10 | N26: 4 | O26: 151553.31 | P26: 10 | Q26: 60621.32 | S26: 84170.38
A27: ORD-10026 | B27: 44822 | C27: 44824 | D27: First Class | E27: Chibundo Sowore | F27: chibundo.sowore@hotmail.com | G27: 9073919694 | H27: Corporate | I27: West | J27: Osogbo | K27: Food & Beverages | L27: Condiments | M27: Soy Sauce 500ml | N27: 1 | O27: 3426.78 | P27: 10 | Q27: 342.68 | R27: 3084.1 | S27: 68.31
A28: ORD-10027 | B28: 45514 | C28: 45517 | D28: First Class | E28: Olumide Sowore | F28: olumide.sowore@yahoo.com | G28: 8158938746 | H28: Home Office | I28: West | J28: Ado-Ekiti | K28: Furniture | L28: Chairs | M28: Visitor Chair | N28: 20 | O28: 96657.75 | P28: 10 | Q28: 193315.5 | R28: 1739839.5 | S28: -163488.68
A29: ORD-10028 | B29: 44863 | C29: 44866 | D29: Second Class | E29: Emeka Abubakar | F29: emeka.abubakar@hotmail.com | G29: 9052221854 | H29: Consumer | I29: South | J29: Benin City | K29: Clothing | L29: Bags | M29: Crossbody Bag | N29: 13 units | O29: 10360.72 | P29: 20 | Q29: 26937.87 | R29: 107751.49 | S29: 9675.19
A30: ORD-10029 | B30: 45010 | C30: 45010 | D30: Same Day | E30: Ronke Fashola | F30: ronke.fashola@gmail.com | G30: 8155180853 | H30: Consumer | I30: South | J30: Lagos | K30: Technology | L30: Accessories | M30: Sunglasses UV400 | N30: 17 | O30: 363616.22 | P30: 25 | Q30: 1545368.9 | R30: 4636106.8 | S30: 960932.31
A31: ORD-10030 | B31: 45475 | C31: 45475 | D31: Same Day | E31: Kunle Fashola | F31: kunle.fashola@outlook.com | G31: 9025147994 | H31: Home Office | I31: West | J31: Ado-Ekiti | K31: Office Supplies | L31: Art Supplies | M31: Craft Scissors | N31: 8 | O31: 12372.63 | P31: 10% | Q31: 9898.1 | R31: 89082.94 | S31: 10148.65
A32: ORD-10031 | B32: 45216 | C32: 45218 | D32: First Class | E32: Kemi Okafor | F32: kemi.okafor@yahoo.com | G32: 7063563646 | H32: Corporate | I32: East | J32: Onitsha | K32: Furniture | L32: Chairs | M32: Bar Stool | N32: 18 | O32: 78107.09 | P32: 20 | Q32: 281185.52 | R32: 1124742.1 | S32: 111871.96
A33: ORD-10032 | B33: 45341 | C33: 45349 | D33: Standard Class | E33: Chidi Adebayo | F33: chidi.adebayo@outlook.com | G33: 9027542890 | H33: Corporate | I33: South | J33: Warri | K33: Clothing | L33: Accessories | M33: Wallet Genuine Leather | N33: 8 | O33: 36394.33 | P33: 20 | Q33: 58230.93 | R33: 232923.71 | S33: -4273.46
A34: ORD-10033 | B34: 45250 | C34: 45251 | D34: Same Day | E34: Aisha Gambo | F34: aisha.gambo@hotmail.com | G34: 8109961107 | H34: Consumer | I34: West | J34: Akure | K34: Technology | L34: Accessories | M34: Wallet Genuine Leather | N34: 1 | O34: 260510.51 | P34: 0 | Q34: 0 | R34: 260510.51 | S34: 61389.25
A35: ORD-10034 | B35: 45094 | C35: 45102 | D35: STANDARD CLASS | E35: Chisom Nwosu | F35: chisom.nwosu@hotmail.com | G35: 7036662319 | H35: Consumer | I35: South | J35: Warri | K35: Clothing | L35: Shoes | M35: Leather Loafers | N35: 3 | O35: 12847.68 | P35: 20 | Q35: 7708.61 | R35: 30834.43 | S35: -4266.56
A36: ORD-10035 | B36: 03/24/2022 | C36: 44649 | D36: Standard Class | E36: Hauwa Nwosu | F36: hauwa.nwosu@gmail.com | G36: 9053556551 | H36: Consumer | I36: North | J36: Abuja | K36: Furniture | L36: Tables | M36: Dining Table 6-Seater | N36: 19 | O36: 123146.92 | P36: 5 | Q36: 116989.57 | R36: 2222801.9 | S36: 286786.77
A37: ORD-10036 | B37: 44897 | C37: 44904 | D37: Standard Class | E37: Yemi Danjuma | F37: spaces in@email.com | G37: 8167296605 | H37: Consumer | I37: East | J37: Aba | K37: Clothing | L37: Trousers | M37: Men's Chinos | N37: 8 | O37: 27460.21 | P37: 0 | Q37: 0 | R37: 219681.68 | S37: 58944.07
A38: ORD-10037 | B38: 45273 | C38: 45281 | D38: Standard Class | E38: Uchenna Musa | F38: uchenna.musa@outlook.com | G38: 8038047416 | H38: Consumer | I38: East | J38: Awka | K38: Clothing | L38: Shirts | M38: T-Shirt 3-Pack | N38: 15 | O38: 43313.87 | P38: 0 | Q38: 0 | R38: 649708.05 | S38: 72307.49
A39: ORD-10038 | B39: 45514 | C39: 45515 | D39: Same Day | E39: Lanre Chukwu | F39: lanre.chukwu@outlook.com | G39: 8035118725 | H39: Home Office | I39: East | J39: Awka | K39: Technology | L39: Tablets | M39: Huawei MatePad | N39: 15 | O39: 121080.6 | P39: 15 | Q39: 272431.35 | R39: 1543777.6 | S39: 80026.3
A40: ORD-10039 | B40: 44996 | C40: 44997 | D40: Same Day | E40: Tobi Osei | F40: tobi.osei@outlook.com | G40: 9055635017 | H40: Consumer | I40: West | J40: Osogbo | K40: Food & Beverages | L40: Drinks | M40: Energy Drink 4-Pack | N40: 3 | O40: 7600.08 | P40: 5 | Q40: 1140.01 | S40: 6109.16
...

Sheet Raw Data (4)
A1: Order ID | B1: Order Date | C1: Ship Date | D1: Ship Mode | E1: First Name | F1: Last Name | G1: Email | H1: Phone | I1: Segment | J1: Region | K1: State | L1: Category | M1: Category Clean | N1: Sub-Category | O1: Product Name | P1: Quantity | Q1: Unit Price (₦) | R1: Discount (%) | S1: Discount Amount (₦) | T1: Sales (₦) | U1: Profit (₦)
A2: ORD-10858 | B2: 44562 | C2: 44567 | D2: Standard Class | E2: Ayo | F2: Adeleke | G2: ayo.adeleke@gmail.com | H2: 8161000159 | I2: Consumer | J2: East | K2: Onitsha | L2: Office Supplies | M2: =TRIM(Table2[[#This Row],[Category]]) -> Office Supplies | N2: Envelopes | O2: Brown Kraft Envelopes | P2: 6 | Q2: 18354.33 | R2: 0 | S2: 0 | T2: 110125.98 | U2: -12981.35
A3: ORD-10441 | B3: 44573 | C3: 44581 | D3: Standard Class | E3: Bola | F3: Okonkwo | G3: bola.okonkwo@yahoo.com | H3: 9079004743 | I3: Corporate | J3: East | K3: Enugu | L3: Clothing | M3: =TRIM(Table2[[#This Row],[Category]]) -> Clothing | N3: Bags | O3: Crossbody Bag | P3: 10 | Q3: 33214.19 | R3: 10 | S3: 33214.19 | T3: 298927.71 | U3: 79035.7
A4: ORD-10505 | B4: 44583 | C4: 44590 | D4: Standard Class | E4: Bola | F4: Obi | G4: bola.obi@yahoo.com | H4: 7038788747 | I4: Corporate | J4: West | K4: Ilorin | L4: Clothing | M4: =TRIM(Table2[[#This Row],[Category]]) -> Clothing | N4: Bags | O4: Laptop Backpack | P4: 8 | Q4: 5549.59 | R4: 20 | S4: 8879.34 | T4: 35517.38 | U4: -2338.7
A5: ORD-10382 | B5: 44607 | C5: 44613 | D5: STANDARD CLASS | E5: Ronke | F5: Tinubu | G5: ronke.tinubu@outlook.com | H5: 7066751103 | I5: Consumer | J5: North | K5: Abuja | L5: Office Supplies | M5: =TRIM(Table2[[#This Row],[Category]]) -> Office Supplies | N5: Envelopes | O5: C5 Envelopes | P5: 17 | Q5: 16813.46 | R5: 25 | S5: 71457.21 | T5: 214371.61 | U5: 25114.44
A6: ORD-10832 | B6: 44609 | C6: 44615 | D6: Standard Class | E6: Yemi | F6: Abubakar | G6: yemi.abubakar@gmail.com | H6: 8107264416 | I6: Home Office | J6: west | K6: Abuja | L6: Technology | M6: =TRIM(Table2[[#This Row],[Category]]) -> Technology | N6: Phones | O6: Xiaomi Redmi 12 | P6: 3 | Q6: 363633.82 | R6: 0 | S6: 0 | T6: 1090901.5 | U6: -157322.01
A7: ORD-10852 | B7: 44611 | C7: 44616 | D7: Standard Class | E7: Zainab | F7: Sanusi | G7: zainab.sanusi@gmail.com | H7: 8034674225 | I7: Consumer | J7: East | K7: Onitsha | L7: Furniture | M7: =TRIM(Table2[[#This Row],[Category]]) -> Furniture | N7: Tables | O7: Conference Table | P7: 11 | Q7: 94100.43 | R7: 15 | S7: 155265.71 | T7: 879839.02 | U7: 267099.63
A8: ORD-10959 | B8: 44624 | C8: 44629 | D8: Standard Class | E8: Chisom | F8: Adeyemi | G8: chisom.adeyemi@gmail.com | H8: 8064194751 | I8: Home Office | J8: North | K8: Kano | L8: Clothing | M8: =TRIM(Table2[[#This Row],[Category]]) -> Clothing | N8: Shirts | O8: T-Shirt 3-Pack | P8: 18 | Q8: 35696.94 | R8: 10 | S8: 64254.49 | T8: 578290.43 | U8: -66880.13
A9: ORD-10160 | B9: 44625 | C9: 44631 | D9: Standard Class | E9: Nike | F9: Adeleke | G9: nike.adeleke@outlook.com | H9: 8135843084 | I9: Consumer | J9: West | K9: Akure | L9: Furniture | M9: =TRIM(Table2[[#This Row],[Category]]) -> Furniture | N9: Storage | O9: Wardrobe 3-Door | P9: 16 | Q9: 135713.14 | R9: 25 | S9: 542852.56 | T9: 1628557.7 | U9: 254842.55
A10: ORD-10364 | B10: 44637 | C10: 44643 | D10: Standard Class | E10: Wale | F10: Tinubu | G10: wale.tinubu@gmail.com | H10: 8141768424 | I10: Consumer | J10: South | K10: Port Harcourt | L10: Furniture | M10: =TRIM(Table2[[#This Row],[Category]]) -> Furniture | N10: Tables | O10: Office Desk 120cm | P10: 2 | Q10: 37626.83 | R10: 10 | S10: 7525.37 | T10: 67728.29 | U10: 23193.11
A11: ORD-10035 | B11: 44644 | C11: 44649 | D11: Standard Class | E11: Hauwa | F11: Nwosu | G11: hauwa.nwosu@gmail.com | H11: 9053556551 | I11: Consumer | J11: North | K11: Abuja | L11: Furniture | M11: =TRIM(Table2[[#This Row],[Category]]) -> Furniture | N11: Tables | O11: Dining Table 6-Seater | P11: 19 | Q11: 123146.92 | R11: 5 | S11: 116989.57 | T11: 2222801.9 | U11: 286786.77
A12: ORD-10296 | B12: 44651 | C12: 44657 | D12: Standard Class | E12: Fatima | F12: Lawal | G12: fatima.lawal@gmail.com | H12: 8132796087 | I12: Home Office | J12: north | K12: Kano | L12: Clothing | M12: =TRIM(Table2[[#This Row],[Category]]) -> Clothing | N12: Trousers | O12: Men's Chinos | P12: 13 | Q12: 3368.14 | R12: 20 | S12: 8757.16 | T12: 35028.66 | U12: 5796.99
A13: ORD-10166 | B13: 44656 | C13: 44661 | D13: Standard Class | E13: Adebayo | F13: Okonkwo | G13: adebayo.okonkwo@gmail.com | H13: 8033650523 | I13: Home Office | J13: West | K13: Osogbo | L13: Clothing | M13: =TRIM(Table2[[#This Row],[Category]]) -> Clothing | N13: Bags | O13: Laptop Backpack | P13: 14 | Q13: 44649.04 | R13: 5 | S13: 31254.33 | T13: 593832.23 | U13: 265690.3
A14: ORD-10092 | B14: 44659 | C14: 44665 | D14: Standard Class | E14: =E15 -> Amara | F14: =F13 -> Okonkwo | G14: chibundo.tinubu@hotmail.com | H14: 8062859886 | I14: Corporate | J14: East | K14: Onitsha | L14: Clothing | M14: =TRIM(Table2[[#This Row],[Category]]) -> Clothing | N14: Accessories | O14: Wallet Genuine Leather | P14: 17 | Q14: 2706.72 | R14: 5 | S14: 2300.71 | T14: 43713.53 | U14: 12289.04
A15: ORD-10221 | B15: 44660 | C15: 44665 | D15: Standard Class | E15: Amara | F15: Adeleke | G15: N/A | H15: 7068454356 | I15: Home Office | J15: East | K15: Awka | L15: Clothing | M15: =TRIM(Table2[[#This Row],[Category]]) -> Clothing | N15: Shirts | O15: Ankara Print Shirt | P15: 5 | Q15: 12867.75 | R15: 5 | S15: 3216.94 | T15: 61121.81 | U15: 16326.57
A16: ORD-10971 | B16: 44660 | C16: 44666 | D16: Standard Class | E16: Hauwa | F16: Danjuma | G16: hauwa.danjuma@gmail.com | H16: 9074321723 | I16: Corporate | J16: West | K16: Ado-Ekiti | L16: Clothing | M16: =TRIM(Table2[[#This Row],[Category]]) -> Clothing | N16: Trousers | O16: Women's Palazzo | P16: 11 | Q16: 19414.76 | R16: 5 | S16: 10678.12 | T16: 202884.24 | U16: -25659.44
A17: ORD-10563 | B17: 44668 | C17: 44675 | D17: Standard Class | E17: Ibrahim | F17: Eze | G17: ibrahim.eze@hotmail.com | H17: 8162690500 | I17: Consumer | J17: North | K17: Kaduna | L17: Clothing | M17: =TRIM(Table2[[#This Row],[Category]]) -> Clothing | N17: Trousers | O17: Joggers | P17: 12 | Q17: 42778.11 | R17: 10 | S17: 51333.73 | T17: 462003.59 | U17: 15067.79
A18: ORD-10621 | B18: 44669 | C18: 44676 | D18: Standard Class | E18: Emeka | F18: Bello | G18: emeka.bello@gmail.com | H18: 8162258998 | I18: Home Office | J18: South | K18: Benin City | L18: Office Supplies | M18: =TRIM(Table2[[#This Row],[Category]]) -> Office Supplies | N18: Pens & Pencils | O18: Highlighters Set | P18: 13 | Q18: 19894.88 | R18: 10 | S18: 25863.34 | T18: 232770.1 | U18: 62661.45
A19: ORD-10127 | B19: 44685 | C19: 44690 | D19: STANDARD CLASS | E19: Kunle | F19: Adeleke | G19: kunle.adeleke@outlook.com | H19: 7064019585 | I19: Corporate | J19: North | K19: Sokoto | L19: Furniture | M19: =TRIM(Table2[[#This Row],[Category]]) -> Furniture | N19: Storage | O19: Plastic Drawers | P19: 13 | Q19: 178771.33 | R19: 20 | S19: 464805.46 | T19: 1859221.8 | U19: 691206.94
A20: ORD-10456 | B20: 44684 | C20: 44691 | D20: Standard Class | E20: Tobi | F20: Tinubu | G20: tobi.tinubu@outlook.com | H20: 8061800824 | I20: Home Office | J20: East | K20: Abia | L20: Technology | M20: =TRIM(Table2[[#This Row],[Category]]) -> Technology | N20: Accessories | O20: Wristwatch | P20: 1 | Q20: 264009.35 | R20: 20 | S20: 52801.87 | T20: 211207.48 | U20: 11275.98
A21: ORD-10782 | B21: 44683 | C21: 44691 | D21: Standard Class | E21: Kemi | F21: Okafor | G21: kemi.okafor@hotmail.com | H21: 8033688598 | I21: Home Office | J21: South | K21: Port Harcourt | L21: Furniture | M21: =TRIM(Table2[[#This Row],[Category]]) -> Furniture | N21: Storage | O21: Filing Cabinet | P21: 13 | Q21: 119126.56 | R21: 5 | S21: 77432.26 | T21: 1471213 | U21: -1259.39
A22: ORD-10567 | B22: 44686 | C22: 44692 | D22: Standard Class | E22: Ikenna | F22: Sanusi | G22: ikenna.sanusi@gmail.com | H22: 8108344141 | I22: Corporate | J22: East | K22: Onitsha | L22: Food & Beverages | M22: =TRIM(Table2[[#This Row],[Category]]) -> Food & Beverages | N22: Cooking Oil | O22: Sunflower Oil 3L | P22: -1 | Q22: 6301.17 | R22: 10 | S22: 8191.52 | T22: 73723.69 | U22: -1905.41
A23: ORD-10173 | B23: 44685 | C23: 44693 | D23: Standard Class | E23: Dayo | F23: Eze | G23: dayo.eze@hotmail.com | H23: 7067749095 | I23: Consumer | J23: North | K23: Abuja | L23: Technology | M23: =TRIM(Table2[[#This Row],[Category]]) -> Technology | N23: Printers | O23: HP LaserJet Pro | P23: 9 | Q23: 282980.47 | R23: 0 | S23: 0 | T23: 2546824.2 | U23: 91543.38
A24: ORD-10070 | B24: 44686 | C24: 44694 | D24: Standard Class | E24: Ikenna | F24: Ogundipe | G24: ikenna.ogundipe@gmail.com | H24: 8148441741 | I24: Home Office | J24: East | K24: Owerri | L24: Technology | M24: =TRIM(Table2[[#This Row],[Category]]) -> Technology | N24: Laptops | O24: Dell Inspiron 15 | P24: 3 | Q24: 279609.38 | R24: 0 | S24: 0 | T24: 838828.14 | U24: 12590.47
A25: ORD-10587 | B25: 44695 | C25: 44701 | D25: Standard Class | E25: Deola | F25: Okonkwo | G25: deola.okonkwo@outlook.com | H25: 8134384399 | I25: Home Office | J25: East | K25: Onitsha | L25: Technology | M25: =TRIM(Table2[[#This Row],[Category]]) -> Technology | N25: Phones | O25: Tecno Spark 10 | P25: 19 | Q25: 51992.12 | R25: 0 | S25: 0 | T25: 987850.28 | U25: 185956.49
A26: ORD-10886 | B26: 44698 | C26: 44704 | D26: Standard Class | E26: Tobi | F26: Sanusi | G26: tobi.sanusi@hotmail.com | H26: 8155648826 | I26: Corporate | J26: WEST | K26: Ado-Ekiti | L26: Food & Beverages | M26: =TRIM(Table2[[#This Row],[Category]]) -> Food & Beverages | N26: Condiments | O26: Pepper Mix 200g | P26: 2 | Q26: 1833.76 | R26: 15 | S26: 550.13 | T26: 3117.39 | U26: 707.23
A27: ORD-10057 | B27: 44702 | C27: 44708 | D27: Standard Class | E27: Nike | F27: Abubakar | G27: nike.abubakar@gmail.com | H27: 7062651601 | I27: Home Office | J27: East | K27: Owerri | L27: Technology | M27: =TRIM(Table2[[#This Row],[Category]]) -> Technology | N27: Accessories | O27: Sunglasses UV400 | P27: 1 | Q27: 316890.51 | R27: 0 | S27: 0 | T27: 316890.51 | U27: 14141.18
A28: ORD-10298 | B28: 44706 | C28: 44713 | D28: Standard Class | E28: Tunde | F28: Nwosu | G28: tunde.nwosu@gmail.com | H28: 8064875838 | I28: Corporate | J28: North | K28: Katsina | L28: Food & Beverages | M28: =TRIM(Table2[[#This Row],[Category]]) -> Food & Beverages | N28: Cooking Oil | O28: Palm Oil 4L | P28: 8 | Q28: 1787.02 | R28: 0 | S28: 0 | T28: 14296.16 | U28: 2645.56
A29: ORD-10523 | B29: 44705 | C29: 44713 | D29: Standard Class | E29: Ronke | F29: Ogundipe | G29: ronke.ogundipe@outlook.com | H29: 9018230134 | I29: Consumer | J29: South | K29: Warri | L29: Furniture | M29: =TRIM(Table2[[#This Row],[Category]]) -> Furniture | N29: Tables | O29: Study Table | P29: 5 | Q29: 40060.81 | R29: 5 | S29: 10015.2 | T29: 190288.85 | U29: 26998.71
A30: ORD-10435 | B30: 44706 | C30: 44714 | D30: Standard Class | E30: Sade | F30: Olawale | G30: sade.olawale@outlook.com | H30: 8105027876 | I30: Corporate | J30: North | K30: Abuja | L30: Clothing | M30: =TRIM(Table2[[#This Row],[Category]]) -> Clothing | N30: Shirts | O30: Men's Polo Shirt | P30: 6 | Q30: 38650.87 | R30: 15 | S30: 34785.78 | T30: 197119.44 | U30: 62623.96
A31: ORD-10494 | B31: 44708 | C31: 44715 | D31: Standard Class | E31: Emeka | F31: Otedola | G31: emeka.otedola@yahoo.com | H31: 7034299177 | I31: Consumer | J31: East | K31: Onitsha | L31: Office Supplies | M31: =TRIM(Table2[[#This Row],[Category]]) -> Office Supplies | N31: Pens & Pencils | O31: Pilot G2 Gel Pens | P31: 9 | Q31: 18757.68 | R31: 5 | S31: 8440.96 | T31: 160378.16 | U31: 43845.08
A32: ORD-10273 | B32: 44722 | C32: 44730 | D32: Standard Class | E32: Ayo | F32: Okonkwo | G32: ayo.okonkwo@gmail.com | H32: 8039091518 | I32: Consumer | J32: East | K32: Onitsha | L32: Office Supplies | M32: =TRIM(Table2[[#This Row],[Category]]) -> Office Supplies | N32: Labels | O32: Price Tag Labels | P32: 19 | Q32: 12562.34 | R32: 10 | S32: 23868.45 | T32: 214816.01 | U32: 31037.31
A33: ORD-10417 | B33: 44733 | C33: 44730 | D33: Standard Class | E33: Deola | F33: Eze | G33: deola.eze@gmail.com | H33: 7067097414 | I33: Consumer | J33: North | K33: Sokoto | L33: Technology | M33: =TRIM(Table2[[#This Row],[Category]]) -> Technology | N33: Accessories | O33: Sunglasses UV400 | P33: 19 | Q33: 117677.9 | R33: 25 | S33: 558970.03 | T33: 1676910.1 | U33: 687132.8
A34: ORD-10835 | B34: 44724 | C34: 44730 | D34: Standard Class | E34: Musa | F34: Chukwu | G34: musa.chukwu@yahoo.com | H34: 8154176691 | I34: Consumer | J34: North | K34: Sokoto | L34: Technology | M34: =TRIM(Table2[[#This Row],[Category]]) -> Technology | N34: Laptops | O34: Lenovo IdeaPad 3 | P34: 11 | Q34: 96365.9 | R34: 5 | S34: 53001.25 | T34: 1007023.7 | U34: -52914.92
A35: ORD-10915 | B35: 44730 | C35: 44735 | D35: Standard Class | E35: Ayo | F35: Okonkwo | G35: ayo.okonkwo@yahoo.com | H35: 9023851025 | I35: Consumer | J35: East | K35: Aba | L35: Clothing | M35: =TRIM(Table2[[#This Row],[Category]]) -> Clothing | N35: Bags | O35: Laptop Backpack | P35: 10 | Q35: 13495.2 | R35: 25 | S35: 33738 | T35: 101214 | U35: -10828.89
A36: ORD-10076 | B36: 44729 | C36: 44736 | D36: Standard Class | E36: Olumide | F36: Sowore | G36: olumide.sowore@hotmail.com | H36: 8148416270 | I36: home office | J36: South | K36: Ibadan | L36: Clothing | M36: =TRIM(Table2[[#This Row],[Category]]) -> Clothing | N36: Shoes | O36: Women's Heels | P36: 4 | Q36: 34462.56 | R36: 10 | S36: 13785.02 | T36: 124065.22 | U36: 13392.61
A37: ORD-10434 | B37: 44728 | C37: 44736 | D37: Standard Class | E37: Kunle | F37: Fashola | G37: kunle.fashola@outlook.com | H37: 9051097397 | I37: Consumer | J37: North | K37: Abuja | L37: Office Supplies | M37: =TRIM(Table2[[#This Row],[Category]]) -> Office Supplies | N37: Paper | O37: Graph Paper Pad | P37: 11 | Q37: 23796.95 | R37: 0 | S37: 0 | T37: 261766.45 | U37: -6067.72
A38: ORD-10972 | B38: 44733 | C38: 44741 | D38: Standard Class | E38: Chisom | F38: Olawale | G38: chisom.olawale@gmail.com | H38: 8149400075 | I38: Home Office | J38: west | K38: Abeokuta | L38: Clothing | M38: =TRIM(Table2[[#This Row],[Category]]) -> Clothing | N38: Accessories | O38: Wallet Genuine Leather | P38: 1 | Q38: 40348.43 | R38: 0 | S38: 0 | T38: 40348.43 | U38: -999.75
A39: ORD-10266 | B39: 44748 | C39: 44754 | D39: Standard Class | E39: Kunle_Alakija | F39: =F38 -> Olawale | G39: kunle.alakija@hotmail.com | H39: 8062075091 | I39: Corporate | J39: North | K39: Kaduna | L39: office supplies | M39: =TRIM(Table2[[#This Row],[Category]]) -> office supplies | N39: Binders | O39: Clipboard | P39: 2 | Q39: 2460.97 | R39: 15 | S39: 738.29 | T39: 4183.65 | U39: 1708.65
A40: ORD-10502 | B40: 44748 | C40: 44755 | D40: Standard Class | E40: =E41 -> Yemi | F40: =F39 -> Olawale | G40: adebayo.adebayo@outlook.com | H40: 7063938131 | I40: Corporate | J40: West | K40: Akure | L40: Clothing | M40: =TRIM(Table2[[#This Row],[Category]]) -> Clothing | N40: Trousers | O40: Women's Palazzo | P40: 14 | Q40: 40698.48 | R40: 20 | S40: 113955.74 | T40: 455822.98 | U40: 36830.04
...

Sheet Raw Data
A1: Order ID | B1: Order Date | C1: Ship Date | D1: Ship Mode | E1: First Name | F1: Last Name | G1: Email | H1: Phone | I1: Segment | J1: Region | K1: State | L1: Category | M1: Sub-Category | N1: Product Name | O1: Quantity | P1: Unit Price (₦) | Q1: Discount (%) | R1: Discount Amount (₦) | S1: Sales (₦) | T1: Profit (₦) | U1: Category_titleCase | V1: ABS(Absolute Value) | W1: Order Classification | X1: Nested If Condition | Y1: Discount Decision
A2: ORD-10858 | B2: 44562 | C2: 44567 | D2: Standard Class | E2: Ayo | F2: Adeleke | G2: ayo.adeleke@gmail.com | H2: 8161000159 | I2: Consumer | J2: East | K2: Onitsha | L2: Office Supplies | M2: Envelopes | N2: Brown Kraft Envelopes | O2: 6 | P2: 18354.33 | Q2: 0 | R2: 0 | S2: 110125.98 | T2: -12981.35 | U2: =PROPER(L2) -> Office Supplies | V2: =ABS(T2) -> 12981.35 | W2: =IF(Sales[[#This Row],[Quantity]]>=15, "Large","Small") -> Small | X2: =IF(Sales[[#This Row],[Quantity]]>=15,"Large",IF(Sales[[#This Row],[Quantity]]=14,"Medium","Small")) -> Small | Y2: =IF(AND(Sales[[#This Row],[Unit Price (₦)]]>68000,Sales[[#This Row],[Quantity]]>15),"Offer Discount", "No Discount") -> No Discount
A3: ORD-10441 | B3: 44573 | C3: 44581 | D3: Standard Class | E3: Bola | F3: Okonkwo | G3: bola.okonkwo@yahoo.com | H3: 9079004743 | I3: Corporate | J3: East | K3: Enugu | L3: Clothing | M3: Bags | N3: Crossbody Bag | O3: 10 | P3: 33214.19 | Q3: 10 | R3: 33214.19 | S3: 298927.71 | T3: 79035.7 | U3: =PROPER(L3) -> Clothing | V3: =ABS(T3) -> 79035.7 | W3: =IF(Sales[[#This Row],[Quantity]]>=15, "Large","Small") -> Small | X3: =IF(Sales[[#This Row],[Quantity]]>=15,"Large",IF(Sales[[#This Row],[Quantity]]=14,"Medium","Small")) -> Small | Y3: =IF(AND(Sales[[#This Row],[Unit Price (₦)]]>68000,Sales[[#This Row],[Quantity]]>15),"Offer Discount", "No Discount") -> No Discount
A4: ORD-10505 | B4: 44583 | C4: 44590 | D4: Standard Class | E4: Bola | F4: Obi | G4: bola.obi@yahoo.com | H4: 7038788747 | I4: Corporate | J4: West | K4: Ilorin | L4: Clothing | M4: Bags | N4: Laptop Backpack | O4: 8 | P4: 5549.59 | Q4: 20 | R4: 8879.34 | S4: 35517.38 | T4: -2338.7 | U4: =PROPER(L4) -> Clothing | V4: =ABS(T4) -> 2338.7 | W4: =IF(Sales[[#This Row],[Quantity]]>=15, "Large","Small") -> Small | X4: =IF(Sales[[#This Row],[Quantity]]>=15,"Large",IF(Sales[[#This Row],[Quantity]]=14,"Medium","Small")) -> Small | Y4: =IF(AND(Sales[[#This Row],[Unit Price (₦)]]>68000,Sales[[#This Row],[Quantity]]>15),"Offer Discount", "No Discount") -> No Discount
A5: ORD-10382 | B5: 44607 | C5: 44613 | D5: Standard Class | E5: Ronke | F5: Tinubu | G5: ronke.tinubu@outlook.com | H5: 7066751103 | I5: Consumer | J5: North | K5: Abuja | L5: Office Supplies | M5: Envelopes | N5: C5 Envelopes | O5: 17 | P5: 16813.46 | Q5: 25 | R5: 71457.21 | S5: 214371.61 | T5: 25114.44 | U5: =PROPER(L5) -> Office Supplies | V5: =ABS(T5) -> 25114.44 | W5: =IF(Sales[[#This Row],[Quantity]]>=15, "Large","Small") -> Large | X5: =IF(Sales[[#This Row],[Quantity]]>=15,"Large",IF(Sales[[#This Row],[Quantity]]=14,"Medium","Small")) -> Large | Y5: =IF(AND(Sales[[#This Row],[Unit Price (₦)]]>68000,Sales[[#This Row],[Quantity]]>15),"Offer Discount", "No Discount") -> No Discount
A6: ORD-10832 | B6: 44609 | C6: 44615 | D6: Standard Class | E6: Yemi | F6: Abubakar | G6: yemi.abubakar@gmail.com | H6: 8107264416 | I6: Home Office | J6: West | K6: Abuja | L6: Technology | M6: Phones | N6: Xiaomi Redmi 12 | O6: 3 | P6: 363633.82 | Q6: 0 | R6: 0 | S6: 1090901.5 | T6: -157322.01 | U6: =PROPER(L6) -> Technology | V6: =ABS(T6) -> 157322.01 | W6: =IF(Sales[[#This Row],[Quantity]]>=15, "Large","Small") -> Small | X6: =IF(Sales[[#This Row],[Quantity]]>=15,"Large",IF(Sales[[#This Row],[Quantity]]=14,"Medium","Small")) -> Small | Y6: =IF(AND(Sales[[#This Row],[Unit Price (₦)]]>68000,Sales[[#This Row],[Quantity]]>15),"Offer Discount", "No Discount") -> No Discount
A7: ORD-10852 | B7: 44611 | C7: 44616 | D7: Standard Class | E7: Zainab | F7: Sanusi | G7: zainab.sanusi@gmail.com | H7: 8034674225 | I7: Consumer | J7: East | K7: Onitsha | L7: Furniture | M7: Tables | N7: Conference Table | O7: 11 | P7: 94100.43 | Q7: 15 | R7: 155265.71 | S7: 879839.02 | T7: 267099.63 | U7: =PROPER(L7) -> Furniture | V7: =ABS(T7) -> 267099.63 | W7: =IF(Sales[[#This Row],[Quantity]]>=15, "Large","Small") -> Small | X7: =IF(Sales[[#This Row],[Quantity]]>=15,"Large",IF(Sales[[#This Row],[Quantity]]=14,"Medium","Small")) -> Small | Y7: =IF(AND(Sales[[#This Row],[Unit Price (₦)]]>68000,Sales[[#This Row],[Quantity]]>15),"Offer Discount", "No Discount") -> No Discount
A8: ORD-10959 | B8: 44624 | C8: 44629 | D8: Standard Class | E8: Chisom | F8: Adeyemi | G8: chisom.adeyemi@gmail.com | H8: 8064194751 | I8: Home Office | J8: North | K8: Kano | L8: Clothing | M8: Shirts | N8: T-Shirt 3-Pack | O8: 18 | P8: 35696.94 | Q8: 10 | R8: 64254.49 | S8: 578290.43 | T8: -66880.13 | U8: =PROPER(L8) -> Clothing | V8: =ABS(T8) -> 66880.13 | W8: =IF(Sales[[#This Row],[Quantity]]>=15, "Large","Small") -> Large | X8: =IF(Sales[[#This Row],[Quantity]]>=15,"Large",IF(Sales[[#This Row],[Quantity]]=14,"Medium","Small")) -> Large | Y8: =IF(AND(Sales[[#This Row],[Unit Price (₦)]]>68000,Sales[[#This Row],[Quantity]]>15),"Offer Discount", "No Discount") -> No Discount
A9: ORD-10160 | B9: 44625 | C9: 44631 | D9: Standard Class | E9: Nike | F9: Adeleke | G9: nike.adeleke@outlook.com | H9: 8135843084 | I9: Consumer | J9: West | K9: Akure | L9: Furniture | M9: Storage | N9: Wardrobe 3-Door | O9: 16 | P9: 135713.14 | Q9: 25 | R9: 542852.56 | S9: 1628557.7 | T9: 254842.55 | U9: =PROPER(L9) -> Furniture | V9: =ABS(T9) -> 254842.55 | W9: =IF(Sales[[#This Row],[Quantity]]>=15, "Large","Small") -> Large | X9: =IF(Sales[[#This Row],[Quantity]]>=15,"Large",IF(Sales[[#This Row],[Quantity]]=14,"Medium","Small")) -> Large | Y9: =IF(AND(Sales[[#This Row],[Unit Price (₦)]]>68000,Sales[[#This Row],[Quantity]]>15),"Offer Discount", "No Discount") -> Offer Discount
A10: ORD-10364 | B10: 44637 | C10: 44643 | D10: Standard Class | E10: Wale | F10: Tinubu | G10: wale.tinubu@gmail.com | H10: 8141768424 | I10: Consumer | J10: South | K10: Port Harcourt | L10: Furniture | M10: Tables | N10: Office Desk 120cm | O10: 2 | P10: 37626.83 | Q10: 10 | R10: 7525.37 | S10: 67728.29 | T10: 23193.11 | U10: =PROPER(L10) -> Furniture | V10: =ABS(T10) -> 23193.11 | W10: =IF(Sales[[#This Row],[Quantity]]>=15, "Large","Small") -> Small | X10: =IF(Sales[[#This Row],[Quantity]]>=15,"Large",IF(Sales[[#This Row],[Quantity]]=14,"Medium","Small")) -> Small | Y10: =IF(AND(Sales[[#This Row],[Unit Price (₦)]]>68000,Sales[[#This Row],[Quantity]]>15),"Offer Discount", "No Discount") -> No Discount
A11: ORD-10035 | B11: 44644 | C11: 44649 | D11: Standard Class | E11: Hauwa | F11: Nwosu | G11: hauwa.nwosu@gmail.com | H11: 9053556551 | I11: Consumer | J11: North | K11: Abuja | L11: Furniture | M11: Tables | N11: Dining Table 6-Seater | O11: 19 | P11: 123146.92 | Q11: 5 | R11: 116989.57 | S11: 2222801.9 | T11: 286786.77 | U11: =PROPER(L11) -> Furniture | V11: =ABS(T11) -> 286786.77 | W11: =IF(Sales[[#This Row],[Quantity]]>=15, "Large","Small") -> Large | X11: =IF(Sales[[#This Row],[Quantity]]>=15,"Large",IF(Sales[[#This Row],[Quantity]]=14,"Medium","Small")) -> Large | Y11: =IF(AND(Sales[[#This Row],[Unit Price (₦)]]>68000,Sales[[#This Row],[Quantity]]>15),"Offer Discount", "No Discount") -> Offer Discount
A12: ORD-10296 | B12: 44651 | C12: 44657 | D12: Standard Class | E12: Fatima | F12: Lawal | G12: fatima.lawal@gmail.com | H12: 8132796087 | I12: Home Office | J12: North | K12: Kano | L12: Clothing | M12: Trousers | N12: Men's Chinos | O12: 13 | P12: 3368.14 | Q12: 20 | R12: 8757.16 | S12: 35028.66 | T12: 5796.99 | U12: =PROPER(L12) -> Clothing | V12: =ABS(T12) -> 5796.99 | W12: =IF(Sales[[#This Row],[Quantity]]>=15, "Large","Small") -> Small | X12: =IF(Sales[[#This Row],[Quantity]]>=15,"Large",IF(Sales[[#This Row],[Quantity]]=14,"Medium","Small")) -> Small | Y12: =IF(AND(Sales[[#This Row],[Unit Price (₦)]]>68000,Sales[[#This Row],[Quantity]]>15),"Offer Discount", "No Discount") -> No Discount
A13: ORD-10166 | B13: 44656 | C13: 44661 | D13: Standard Class | E13: Adebayo | F13: Okonkwo | G13: adebayo.okonkwo@gmail.com | H13: 8033650523 | I13: Home Office | J13: West | K13: Osogbo | L13: Clothing | M13: Bags | N13: Laptop Backpack | O13: 14 | P13: 44649.04 | Q13: 5 | R13: 31254.33 | S13: 593832.23 | T13: 265690.3 | U13: =PROPER(L13) -> Clothing | V13: =ABS(T13) -> 265690.3 | W13: =IF(Sales[[#This Row],[Quantity]]>=15, "Large","Small") -> Small | X13: =IF(Sales[[#This Row],[Quantity]]>=15,"Large",IF(Sales[[#This Row],[Quantity]]=14,"Medium","Small")) -> Medium | Y13: =IF(AND(Sales[[#This Row],[Unit Price (₦)]]>68000,Sales[[#This Row],[Quantity]]>15),"Offer Discount", "No Discount") -> No Discount
A14: ORD-10092 | B14: 44659 | C14: 44665 | D14: Standard Class | E14: =E15 -> Amara | F14: =F13 -> Okonkwo | G14: chibundo.tinubu@hotmail.com | H14: 8062859886 | I14: Corporate | J14: East | K14: Onitsha | L14: Clothing | M14: Accessories | N14: Wallet Genuine Leather | O14: 17 | P14: 2706.72 | Q14: 5 | R14: 2300.71 | S14: 43713.53 | T14: 12289.04 | U14: =PROPER(L14) -> Clothing | V14: =ABS(T14) -> 12289.04 | W14: =IF(Sales[[#This Row],[Quantity]]>=15, "Large","Small") -> Large | X14: =IF(Sales[[#This Row],[Quantity]]>=15,"Large",IF(Sales[[#This Row],[Quantity]]=14,"Medium","Small")) -> Large | Y14: =IF(AND(Sales[[#This Row],[Unit Price (₦)]]>68000,Sales[[#This Row],[Quantity]]>15),"Offer Discount", "No Discount") -> No Discount
A15: ORD-10221 | B15: 44660 | C15: 44665 | D15: Standard Class | E15: Amara | F15: Adeleke | G15: N/A | H15: 7068454356 | I15: Home Office | J15: East | K15: Awka | L15: Clothing | M15: Shirts | N15: Ankara Print Shirt | O15: 5 | P15: 12867.75 | Q15: 5 | R15: 3216.94 | S15: 61121.81 | T15: 16326.57 | U15: =PROPER(L15) -> Clothing | V15: =ABS(T15) -> 16326.57 | W15: =IF(Sales[[#This Row],[Quantity]]>=15, "Large","Small") -> Small | X15: =IF(Sales[[#This Row],[Quantity]]>=15,"Large",IF(Sales[[#This Row],[Quantity]]=14,"Medium","Small")) -> Small | Y15: =IF(AND(Sales[[#This Row],[Unit Price (₦)]]>68000,Sales[[#This Row],[Quantity]]>15),"Offer Discount", "No Discount") -> No Discount
A16: ORD-10971 | B16: 44660 | C16: 44666 | D16: Standard Class | E16: Hauwa | F16: Danjuma | G16: hauwa.danjuma@gmail.com | H16: 9074321723 | I16: Corporate | J16: West | K16: Ado-Ekiti | L16: Clothing | M16: Trousers | N16: Women's Palazzo | O16: 11 | P16: 19414.76 | Q16: 5 | R16: 10678.12 | S16: 202884.24 | T16: -25659.44 | U16: =PROPER(L16) -> Clothing | V16: =ABS(T16) -> 25659.44 | W16: =IF(Sales[[#This Row],[Quantity]]>=15, "Large","Small") -> Small | X16: =IF(Sales[[#This Row],[Quantity]]>=15,"Large",IF(Sales[[#This Row],[Quantity]]=14,"Medium","Small")) -> Small | Y16: =IF(AND(Sales[[#This Row],[Unit Price (₦)]]>68000,Sales[[#This Row],[Quantity]]>15),"Offer Discount", "No Discount") -> No Discount
A17: ORD-10563 | B17: 44668 | C17: 44675 | D17: Standard Class | E17: Ibrahim | F17: Eze | G17: ibrahim.eze@hotmail.com | H17: 8162690500 | I17: Consumer | J17: North | K17: Kaduna | L17: Clothing | M17: Trousers | N17: Joggers | O17: 12 | P17: 42778.11 | Q17: 10 | R17: 51333.73 | S17: 462003.59 | T17: 15067.79 | U17: =PROPER(L17) -> Clothing | V17: =ABS(T17) -> 15067.79 | W17: =IF(Sales[[#This Row],[Quantity]]>=15, "Large","Small") -> Small | X17: =IF(Sales[[#This Row],[Quantity]]>=15,"Large",IF(Sales[[#This Row],[Quantity]]=14,"Medium","Small")) -> Small | Y17: =IF(AND(Sales[[#This Row],[Unit Price (₦)]]>68000,Sales[[#This Row],[Quantity]]>15),"Offer Discount", "No Discount") -> No Discount
A18: ORD-10621 | B18: 44669 | C18: 44676 | D18: Standard Class | E18: Emeka | F18: Bello | G18: emeka.bello@gmail.com | H18: 8162258998 | I18: Home Office | J18: South | K18: Benin City | L18: Office Supplies | M18: Pens & Pencils | N18: Highlighters Set | O18: 13 | P18: 19894.88 | Q18: 10 | R18: 25863.34 | S18: 232770.1 | T18: 62661.45 | U18: =PROPER(L18) -> Office Supplies | V18: =ABS(T18) -> 62661.45 | W18: =IF(Sales[[#This Row],[Quantity]]>=15, "Large","Small") -> Small | X18: =IF(Sales[[#This Row],[Quantity]]>=15,"Large",IF(Sales[[#This Row],[Quantity]]=14,"Medium","Small")) -> Small | Y18: =IF(AND(Sales[[#This Row],[Unit Price (₦)]]>68000,Sales[[#This Row],[Quantity]]>15),"Offer Discount", "No Discount") -> No Discount
A19: ORD-10127 | B19: 44685 | C19: 44690 | D19: Standard Class | E19: Kunle | F19: Adeleke | G19: kunle.adeleke@outlook.com | H19: 7064019585 | I19: Corporate | J19: North | K19: Sokoto | L19: Furniture | M19: Storage | N19: Plastic Drawers | O19: 13 | P19: 178771.33 | Q19: 20 | R19: 464805.46 | S19: 1859221.8 | T19: 691206.94 | U19: =PROPER(L19) -> Furniture | V19: =ABS(T19) -> 691206.94 | W19: =IF(Sales[[#This Row],[Quantity]]>=15, "Large","Small") -> Small | X19: =IF(Sales[[#This Row],[Quantity]]>=15,"Large",IF(Sales[[#This Row],[Quantity]]=14,"Medium","Small")) -> Small | Y19: =IF(AND(Sales[[#This Row],[Unit Price (₦)]]>68000,Sales[[#This Row],[Quantity]]>15),"Offer Discount", "No Discount") -> No Discount
A20: ORD-10456 | B20: 44684 | C20: 44691 | D20: Standard Class | E20: Tobi | F20: Tinubu | G20: tobi.tinubu@outlook.com | H20: 8061800824 | I20: Home Office | J20: East | K20: Abia | L20: Technology | M20: Accessories | N20: Wristwatch | O20: 1 | P20: 264009.35 | Q20: 20 | R20: 52801.87 | S20: 211207.48 | T20: 11275.98 | U20: =PROPER(L20) -> Technology | V20: =ABS(T20) -> 11275.98 | W20: =IF(Sales[[#This Row],[Quantity]]>=15, "Large","Small") -> Small | X20: =IF(Sales[[#This Row],[Quantity]]>=15,"Large",IF(Sales[[#This Row],[Quantity]]=14,"Medium","Small")) -> Small | Y20: =IF(AND(Sales[[#This Row],[Unit Price (₦)]]>68000,Sales[[#This Row],[Quantity]]>15),"Offer Discount", "No Discount") -> No Discount
A21: ORD-10782 | B21: 44683 | C21: 44691 | D21: Standard Class | E21: Kemi | F21: Okafor | G21: kemi.okafor@hotmail.com | H21: 8033688598 | I21: Home Office | J21: South | K21: Port Harcourt | L21: Furniture | M21: Storage | N21: Filing Cabinet | O21: 13 | P21: 119126.56 | Q21: 5 | R21: 77432.26 | S21: 1471213 | T21: -1259.39 | U21: =PROPER(L21) -> Furniture | V21: =ABS(T21) -> 1259.39 | W21: =IF(Sales[[#This Row],[Quantity]]>=15, "Large","Small") -> Small | X21: =IF(Sales[[#This Row],[Quantity]]>=15,"Large",IF(Sales[[#This Row],[Quantity]]=14,"Medium","Small")) -> Small | Y21: =IF(AND(Sales[[#This Row],[Unit Price (₦)]]>68000,Sales[[#This Row],[Quantity]]>15),"Offer Discount", "No Discount") -> No Discount
A22: ORD-10567 | B22: 44686 | C22: 44692 | D22: Standard Class | E22: Ikenna | F22: Sanusi | G22: ikenna.sanusi@gmail.com | H22: 8108344141 | I22: Corporate | J22: East | K22: Onitsha | L22: Food & Beverages | M22: Cooking Oil | N22: Sunflower Oil 3L | O22: -1 | P22: 6301.17 | Q22: 10 | R22: 8191.52 | S22: 73723.69 | T22: -1905.41 | U22: =PROPER(L22) -> Food & Beverages | V22: =ABS(T22) -> 1905.41 | W22: =IF(Sales[[#This Row],[Quantity]]>=15, "Large","Small") -> Small | X22: =IF(Sales[[#This Row],[Quantity]]>=15,"Large",IF(Sales[[#This Row],[Quantity]]=14,"Medium","Small")) -> Small | Y22: =IF(AND(Sales[[#This Row],[Unit Price (₦)]]>68000,Sales[[#This Row],[Quantity]]>15),"Offer Discount", "No Discount") -> No Discount
A23: ORD-10173 | B23: 44685 | C23: 44693 | D23: Standard Class | E23: Dayo | F23: Eze | G23: dayo.eze@hotmail.com | H23: 7067749095 | I23: Consumer | J23: North | K23: Abuja | L23: Technology | M23: Printers | N23: HP LaserJet Pro | O23: 9 | P23: 282980.47 | Q23: 0 | R23: 0 | S23: 2546824.2 | T23: 91543.38 | U23: =PROPER(L23) -> Technology | V23: =ABS(T23) -> 91543.38 | W23: =IF(Sales[[#This Row],[Quantity]]>=15, "Large","Small") -> Small | X23: =IF(Sales[[#This Row],[Quantity]]>=15,"Large",IF(Sales[[#This Row],[Quantity]]=14,"Medium","Small")) -> Small | Y23: =IF(AND(Sales[[#This Row],[Unit Price (₦)]]>68000,Sales[[#This Row],[Quantity]]>15),"Offer Discount", "No Discount") -> No Discount
A24: ORD-10070 | B24: 44686 | C24: 44694 | D24: Standard Class | E24: Ikenna | F24: Ogundipe | G24: ikenna.ogundipe@gmail.com | H24: 8148441741 | I24: Home Office | J24: East | K24: Owerri | L24: Technology | M24: Laptops | N24: Dell Inspiron 15 | O24: 3 | P24: 279609.38 | Q24: 0 | R24: 0 | S24: 838828.14 | T24: 12590.47 | U24: =PROPER(L24) -> Technology | V24: =ABS(T24) -> 12590.47 | W24: =IF(Sales[[#This Row],[Quantity]]>=15, "Large","Small") -> Small | X24: =IF(Sales[[#This Row],[Quantity]]>=15,"Large",IF(Sales[[#This Row],[Quantity]]=14,"Medium","Small")) -> Small | Y24: =IF(AND(Sales[[#This Row],[Unit Price (₦)]]>68000,Sales[[#This Row],[Quantity]]>15),"Offer Discount", "No Discount") -> No Discount
A25: ORD-10587 | B25: 44695 | C25: 44701 | D25: Standard Class | E25: Deola | F25: Okonkwo | G25: deola.okonkwo@outlook.com | H25: 8134384399 | I25: Home Office | J25: East | K25: Onitsha | L25: Technology | M25: Phones | N25: Tecno Spark 10 | O25: 19 | P25: 51992.12 | Q25: 0 | R25: 0 | S25: 987850.28 | T25: 185956.49 | U25: =PROPER(L25) -> Technology | V25: =ABS(T25) -> 185956.49 | W25: =IF(Sales[[#This Row],[Quantity]]>=15, "Large","Small") -> Large | X25: =IF(Sales[[#This Row],[Quantity]]>=15,"Large",IF(Sales[[#This Row],[Quantity]]=14,"Medium","Small")) -> Large | Y25: =IF(AND(Sales[[#This Row],[Unit Price (₦)]]>68000,Sales[[#This Row],[Quantity]]>15),"Offer Discount", "No Discount") -> No Discount
A26: ORD-10886 | B26: 44698 | C26: 44704 | D26: Standard Class | E26: Tobi | F26: Sanusi | G26: tobi.sanusi@hotmail.com | H26: 8155648826 | I26: Corporate | J26: West | K26: Ado-Ekiti | L26: Food & Beverages | M26: Condiments | N26: Pepper Mix 200g | O26: 2 | P26: 1833.76 | Q26: 15 | R26: 550.13 | S26: 3117.39 | T26: 707.23 | U26: =PROPER(L26) -> Food & Beverages | V26: =ABS(T26) -> 707.23 | W26: =IF(Sales[[#This Row],[Quantity]]>=15, "Large","Small") -> Small | X26: =IF(Sales[[#This Row],[Quantity]]>=15,"Large",IF(Sales[[#This Row],[Quantity]]=14,"Medium","Small")) -> Small | Y26: =IF(AND(Sales[[#This Row],[Unit Price (₦)]]>68000,Sales[[#This Row],[Quantity]]>15),"Offer Discount", "No Discount") -> No Discount
